<?xml version="1.0" encoding="UTF-8"?>
<testsuite name="Test"
           tests="5"
           failures="3"
           errors="0"
           skipped="0"
           time="0.014">
  <properties />
            <testcase name="test3" time="0.001" classname="com.webtest.demo.TestCheck">
                <failure type="java.lang.AssertionError"
                  message="expected [3] but found [1]"
              >
<![CDATA[java.lang.AssertionError: expected [3] but found [1]
  org.testng.Assert.fail(Assert.java:96)
  org.testng.Assert.failNotEquals(Assert.java:776)
  org.testng.Assert.assertEqualsImpl(Assert.java:137)
  org.testng.Assert.assertEquals(Assert.java:118)
  org.testng.Assert.assertEquals(Assert.java:652)
  org.testng.Assert.assertEquals(Assert.java:662)
  com.webtest.demo.TestCheck.test3(TestCheck.java:25)
  sun.reflect.NativeMethodAccessorImpl.invoke0(Native Method)
  sun.reflect.NativeMethodAccessorImpl.invoke(Unknown Source)
  sun.reflect.DelegatingMethodAccessorImpl.invoke(Unknown Source)
  java.lang.reflect.Method.invoke(Unknown Source)
  org.testng.internal.MethodInvocationHelper.invokeMethod(MethodInvocationHelper.java:124)
  org.testng.internal.Invoker.invokeMethod(Invoker.java:583)
  org.testng.internal.Invoker.invokeTestMethod(Invoker.java:719)
  org.testng.internal.Invoker.invokeTestMethods(Invoker.java:989)
  org.testng.internal.TestMethodWorker.invokeTestMethods(TestMethodWorker.java:125)
  org.testng.internal.TestMethodWorker.run(TestMethodWorker.java:109)
  org.testng.TestRunner.privateRun(TestRunner.java:648)
  org.testng.TestRunner.run(TestRunner.java:505)
  org.testng.SuiteRunner.runTest(SuiteRunner.java:455)
  org.testng.SuiteRunner.runSequentially(SuiteRunner.java:450)
  org.testng.SuiteRunner.privateRun(SuiteRunner.java:415)
  org.testng.SuiteRunner.run(SuiteRunner.java:364)
  org.testng.SuiteRunnerWorker.runSuite(SuiteRunnerWorker.java:52)
  org.testng.SuiteRunnerWorker.run(SuiteRunnerWorker.java:84)
  org.testng.TestNG.runSuitesSequentially(TestNG.java:1208)
  org.testng.TestNG.runSuitesLocally(TestNG.java:1137)
  org.testng.TestNG.runSuites(TestNG.java:1049)
  org.testng.TestNG.run(TestNG.java:1017)
  org.testng.remote.AbstractRemoteTestNG.run(AbstractRemoteTestNG.java:115)
  org.testng.remote.RemoteTestNG.initAndRun(RemoteTestNG.java:251)
  org.testng.remote.RemoteTestNG.main(RemoteTestNG.java:77)
]]>
      </failure>

          </testcase>
            <testcase name="test5" time="0.001" classname="com.webtest.demo.TestCheck">
                <failure type="java.lang.AssertionError"
                  message="expected [3] but found [2]"
              >
<![CDATA[java.lang.AssertionError: expected [3] but found [2]
  org.testng.Assert.fail(Assert.java:96)
  org.testng.Assert.failNotEquals(Assert.java:776)
  org.testng.Assert.assertEqualsImpl(Assert.java:137)
  org.testng.Assert.assertEquals(Assert.java:118)
  org.testng.Assert.assertEquals(Assert.java:652)
  org.testng.Assert.assertEquals(Assert.java:662)
  com.webtest.demo.TestCheck.test5(TestCheck.java:35)
  sun.reflect.NativeMethodAccessorImpl.invoke0(Native Method)
  sun.reflect.NativeMethodAccessorImpl.invoke(Unknown Source)
  sun.reflect.DelegatingMethodAccessorImpl.invoke(Unknown Source)
  java.lang.reflect.Method.invoke(Unknown Source)
  org.testng.internal.MethodInvocationHelper.invokeMethod(MethodInvocationHelper.java:124)
  org.testng.internal.Invoker.invokeMethod(Invoker.java:583)
  org.testng.internal.Invoker.invokeTestMethod(Invoker.java:719)
  org.testng.internal.Invoker.invokeTestMethods(Invoker.java:989)
  org.testng.internal.TestMethodWorker.invokeTestMethods(TestMethodWorker.java:125)
  org.testng.internal.TestMethodWorker.run(TestMethodWorker.java:109)
  org.testng.TestRunner.privateRun(TestRunner.java:648)
  org.testng.TestRunner.run(TestRunner.java:505)
  org.testng.SuiteRunner.runTest(SuiteRunner.java:455)
  org.testng.SuiteRunner.runSequentially(SuiteRunner.java:450)
  org.testng.SuiteRunner.privateRun(SuiteRunner.java:415)
  org.testng.SuiteRunner.run(SuiteRunner.java:364)
  org.testng.SuiteRunnerWorker.runSuite(SuiteRunnerWorker.java:52)
  org.testng.SuiteRunnerWorker.run(SuiteRunnerWorker.java:84)
  org.testng.TestNG.runSuitesSequentially(TestNG.java:1208)
  org.testng.TestNG.runSuitesLocally(TestNG.java:1137)
  org.testng.TestNG.runSuites(TestNG.java:1049)
  org.testng.TestNG.run(TestNG.java:1017)
  org.testng.remote.AbstractRemoteTestNG.run(AbstractRemoteTestNG.java:115)
  org.testng.remote.RemoteTestNG.initAndRun(RemoteTestNG.java:251)
  org.testng.remote.RemoteTestNG.main(RemoteTestNG.java:77)
]]>
      </failure>

          </testcase>
            <testcase name="test2" time="0.002" classname="com.webtest.demo.TestCheck">
                <failure type="java.lang.AssertionError"
                  message="expected [2] but found [1]"
              >
<![CDATA[java.lang.AssertionError: expected [2] but found [1]
  org.testng.Assert.fail(Assert.java:96)
  org.testng.Assert.failNotEquals(Assert.java:776)
  org.testng.Assert.assertEqualsImpl(Assert.java:137)
  org.testng.Assert.assertEquals(Assert.java:118)
  org.testng.Assert.assertEquals(Assert.java:652)
  org.testng.Assert.assertEquals(Assert.java:662)
  com.webtest.demo.TestCheck.test2(TestCheck.java:20)
  sun.reflect.NativeMethodAccessorImpl.invoke0(Native Method)
  sun.reflect.NativeMethodAccessorImpl.invoke(Unknown Source)
  sun.reflect.DelegatingMethodAccessorImpl.invoke(Unknown Source)
  java.lang.reflect.Method.invoke(Unknown Source)
  org.testng.internal.MethodInvocationHelper.invokeMethod(MethodInvocationHelper.java:124)
  org.testng.internal.Invoker.invokeMethod(Invoker.java:583)
  org.testng.internal.Invoker.invokeTestMethod(Invoker.java:719)
  org.testng.internal.Invoker.invokeTestMethods(Invoker.java:989)
  org.testng.internal.TestMethodWorker.invokeTestMethods(TestMethodWorker.java:125)
  org.testng.internal.TestMethodWorker.run(TestMethodWorker.java:109)
  org.testng.TestRunner.privateRun(TestRunner.java:648)
  org.testng.TestRunner.run(TestRunner.java:505)
  org.testng.SuiteRunner.runTest(SuiteRunner.java:455)
  org.testng.SuiteRunner.runSequentially(SuiteRunner.java:450)
  org.testng.SuiteRunner.privateRun(SuiteRunner.java:415)
  org.testng.SuiteRunner.run(SuiteRunner.java:364)
  org.testng.SuiteRunnerWorker.runSuite(SuiteRunnerWorker.java:52)
  org.testng.SuiteRunnerWorker.run(SuiteRunnerWorker.java:84)
  org.testng.TestNG.runSuitesSequentially(TestNG.java:1208)
  org.testng.TestNG.runSuitesLocally(TestNG.java:1137)
  org.testng.TestNG.runSuites(TestNG.java:1049)
  org.testng.TestNG.run(TestNG.java:1017)
  org.testng.remote.AbstractRemoteTestNG.run(AbstractRemoteTestNG.java:115)
  org.testng.remote.RemoteTestNG.initAndRun(RemoteTestNG.java:251)
  org.testng.remote.RemoteTestNG.main(RemoteTestNG.java:77)
]]>
      </failure>

          </testcase>
  
  
            <testcase name="test4" time="0.001" classname="com.webtest.demo.TestCheck" />
                <testcase name="test1" time="0.009" classname="com.webtest.demo.TestCheck" />
      
</testsuite>
